<?xml version="1.0" ?>
<robot name="ragnar" xmlns:xacro="http://ros.org/wiki/xacro">
  <xacro:macro name="ragnar_upper" params="num x y z r p w"> 
    
    <link name="upper_arm_${num}">
    <inertial>
      <origin xyz="-0.210332479810488 0.0724062934273924 0.00909438990065303" rpy="0 0 0" />
      <mass value="0.220403356973371" />
      <inertia ixx="0.0026219178052145" ixy="-0.000147380937793557" ixz="-1.99584635831913E-05"
        iyy="0.000216359248260153" iyz="0.000315156110780191" izz="0.00261966224861175" />
    </inertial>
    <visual>
      <origin xyz="0 0 0" rpy="0 0 0" />
      <geometry>
        <mesh filename="package://ragnar_support/meshes/upper_arm_${num}.STL" />
      </geometry>
      <material name="">
        <color rgba="0.792156862745098 0.819607843137255 0.933333333333333 1" />
      </material>
    </visual>
    <collision>
      <origin xyz="0 0 0" rpy="0 0 0" />
      <geometry>
        <mesh filename="package://ragnar_support/meshes/upper_arm_${num}.STL" />
      </geometry>
    </collision>
  </link>
  <joint name="a${num}_j1" type="revolute">
    <origin xyz="${x} ${y} ${z}" rpy="${r} ${p} ${w}" />
    <parent link="base_link" />
    <child link="upper_arm_${num}" />
    <axis xyz="-1.0 0 0" />
    <limit effort="0" lower="-3.1416" upper="3.1416" velocity="2.618"/>
  </joint>

    <!--xacro:include filename="$(find ragnar_support)/urdf/ragnar_lower_macro.xacro"/>
    <xacro:ragnar_lower prefix=""/-->

  </xacro:macro>
</robot>
