<?xml version="1.0" ?>
<!-- =================================================================================== -->
<!-- |    This document was autogenerated by xacro from Ragnar.xacro                   | -->
<!-- |    EDITING THIS FILE BY HAND IS NOT RECOMMENDED                                 | -->
<!-- =================================================================================== -->
<robot name="ragnar" xmlns:xacro="http://ros.org/wiki/xacro">
  <link name="base_link">
    <inertial>
      <origin rpy="0 0 0" xyz="-4.80572213006859E-06 9.64495107789746E-06 -0.0184680705713898"/>
      <mass value="26.5217124601092"/>
      <inertia ixx="0.936457909215975" ixy="-0.00108838510526368" ixz="1.58187182756307E-06" iyy="1.50216890338436" iyz="1.0107984651762E-05" izz="2.28323593907717"/>
    </inertial>
    <visual>
      <origin rpy="0 0 0" xyz="0 0 0"/>
      <geometry>
        <mesh filename="package://ragnar_support/meshes/base_link.STL"/>
      </geometry>
      <material name="">
        <color rgba="0.752941176470588 0.752941176470588 0.752941176470588 1"/>
      </material>
    </visual>
    <collision>
      <origin rpy="0 0 0" xyz="0 0 0"/>
      <geometry>
        <mesh filename="package://ragnar_support/meshes/base_link.STL"/>
      </geometry>
    </collision>
  </link>
  <link name="upper_arm_1">
    <inertial>
      <origin rpy="0 0 0" xyz="-0.210332479810488 0.0724062934273924 0.00909438990065303"/>
      <mass value="0.220403356973371"/>
      <inertia ixx="0.0026219178052145" ixy="-0.000147380937793557" ixz="-1.99584635831913E-05" iyy="0.000216359248260153" iyz="0.000315156110780191" izz="0.00261966224861175"/>
    </inertial>
    <visual>
      <origin rpy="0 0 0" xyz="0 0 0"/>
      <geometry>
        <mesh filename="package://ragnar_support/meshes/upper_arm_1.STL"/>
      </geometry>
      <material name="">
        <color rgba="0.792156862745098 0.819607843137255 0.933333333333333 1"/>
      </material>
    </visual>
    <collision>
      <origin rpy="0 0 0" xyz="0 0 0"/>
      <geometry>
        <mesh filename="package://ragnar_support/meshes/upper_arm_1.STL"/>
      </geometry>
    </collision>
  </link>
  <joint name="a1_j1" type="revolute">
    <origin rpy="-0.577 -0.783 -1.311" xyz="0.16 0.108 0.0576"/>
    <parent link="base_link"/>
    <child link="upper_arm_1"/>
    <axis xyz="-1.0 0 0"/>
    <limit effort="0" lower="-3.1416" upper="3.1416" velocity="2.618"/>
  </joint>
  <link name="upper_arm_2">
    <inertial>
      <origin rpy="0 0 0" xyz="-0.210332479810488 0.0724062934273924 0.00909438990065303"/>
      <mass value="0.220403356973371"/>
      <inertia ixx="0.0026219178052145" ixy="-0.000147380937793557" ixz="-1.99584635831913E-05" iyy="0.000216359248260153" iyz="0.000315156110780191" izz="0.00261966224861175"/>
    </inertial>
    <visual>
      <origin rpy="0 0 0" xyz="0 0 0"/>
      <geometry>
        <mesh filename="package://ragnar_support/meshes/upper_arm_2.STL"/>
      </geometry>
      <material name="">
        <color rgba="0.792156862745098 0.819607843137255 0.933333333333333 1"/>
      </material>
    </visual>
    <collision>
      <origin rpy="0 0 0" xyz="0 0 0"/>
      <geometry>
        <mesh filename="package://ragnar_support/meshes/upper_arm_2.STL"/>
      </geometry>
    </collision>
  </link>
  <joint name="a2_j1" type="revolute">
    <origin rpy="-2.698 -0.788 -1.834" xyz="-0.143 0.172 -0.0087"/>
    <parent link="base_link"/>
    <child link="upper_arm_2"/>
    <axis xyz="-1.0 0 0"/>
    <limit effort="0" lower="-3.1416" upper="3.1416" velocity="2.618"/>
  </joint>
  <link name="upper_arm_3">
    <inertial>
      <origin rpy="0 0 0" xyz="-0.210332479810488 0.0724062934273924 0.00909438990065303"/>
      <mass value="0.220403356973371"/>
      <inertia ixx="0.0026219178052145" ixy="-0.000147380937793557" ixz="-1.99584635831913E-05" iyy="0.000216359248260153" iyz="0.000315156110780191" izz="0.00261966224861175"/>
    </inertial>
    <visual>
      <origin rpy="0 0 0" xyz="0 0 0"/>
      <geometry>
        <mesh filename="package://ragnar_support/meshes/upper_arm_3.STL"/>
      </geometry>
      <material name="">
        <color rgba="0.792156862745098 0.819607843137255 0.933333333333333 1"/>
      </material>
    </visual>
    <collision>
      <origin rpy="0 0 0" xyz="0 0 0"/>
      <geometry>
        <mesh filename="package://ragnar_support/meshes/upper_arm_3.STL"/>
      </geometry>
    </collision>
  </link>
  <joint name="a3_j1" type="revolute">
    <origin rpy="-0.456 -0.783 1.831" xyz="-0.122 -0.249 -0.0877"/>
    <parent link="base_link"/>
    <child link="upper_arm_3"/>
    <axis xyz="-1.0 0 0"/>
    <limit effort="0" lower="-3.1416" upper="3.1416" velocity="2.618"/>
  </joint>
  <link name="upper_arm_4">
    <inertial>
      <origin rpy="0 0 0" xyz="-0.210332479810488 0.0724062934273924 0.00909438990065303"/>
      <mass value="0.220403356973371"/>
      <inertia ixx="0.0026219178052145" ixy="-0.000147380937793557" ixz="-1.99584635831913E-05" iyy="0.000216359248260153" iyz="0.000315156110780191" izz="0.00261966224861175"/>
    </inertial>
    <visual>
      <origin rpy="0 0 0" xyz="0 0 0"/>
      <geometry>
        <mesh filename="package://ragnar_support/meshes/upper_arm_4.STL"/>
      </geometry>
      <material name="">
        <color rgba="0.792156862745098 0.819607843137255 0.933333333333333 1"/>
      </material>
    </visual>
    <collision>
      <origin rpy="0 0 0" xyz="0 0 0"/>
      <geometry>
        <mesh filename="package://ragnar_support/meshes/upper_arm_4.STL"/>
      </geometry>
    </collision>
  </link>
  <joint name="a4_j1" type="revolute">
    <origin rpy="-2.531 -0.788 1.307" xyz="0.133 -0.211 -0.0487"/>
    <parent link="base_link"/>
    <child link="upper_arm_4"/>
    <axis xyz="-1.0 0 0"/>
    <limit effort="0" lower="-3.1416" upper="3.1416" velocity="2.618"/>
  </joint>
</robot>

