<?xml version="1.0" ?>
<!-- =================================================================================== -->
<!-- |    This document was autogenerated by xacro from ragnar.xacro                   | -->
<!-- |    EDITING THIS FILE BY HAND IS NOT RECOMMENDED                                 | -->
<!-- =================================================================================== -->
<robot name="Ragnar" xmlns:xacro="http://ros.org/wiki/xacro">
  <link name="base_link"/>
  <link name="base_link2">
    <inertial>
      <origin rpy="0 0 0" xyz="-4.80572213006859E-06 9.64495107789746E-06 -0.0184680705713898"/>
      <mass value="26.5217124601092"/>
      <inertia ixx="0.936457909215975" ixy="-0.00108838510526368" ixz="1.58187182756307E-06" iyy="1.50216890338436" iyz="1.0107984651762E-05" izz="2.28323593907717"/>
    </inertial>
    <visual>
      <origin rpy="0 0 0" xyz="0 0 0"/>
      <geometry>
        <mesh filename="package://ragnar_support/meshes/base_link.STL"/>
      </geometry>
      <material name="">
        <color rgba="0.5 0.5 0.5 1"/>
      </material>
    </visual>
    <collision>
      <origin rpy="0 0 0" xyz="0 0 0"/>
      <geometry>
        <mesh filename="package://ragnar_support/meshes/base_link.STL"/>
      </geometry>
    </collision>
  </link>
  <joint name="base_rotate" type="fixed">
    <origin rpy="0 0 1.57" xyz="0 0 0.05"/>
    <parent link="base_link"/>
    <child link="base_link2"/>
    <axis xyz="0 0 0"/>
  </joint>
  <link name="upper_arm_1">
    <visual>
      <origin rpy="0 1.57 0" xyz="0 0 0"/>
      <geometry>
        <cylinder length="0.1" radius="0.04"/>
      </geometry>
      <material name="">
        <color rgba="0.65 0.65 0.65 1"/>
      </material>
    </visual>
    <visual>
      <origin rpy="1.57 0 0" xyz="0 0.15 0"/>
      <geometry>
        <cylinder length="0.3" radius="0.02"/>
      </geometry>
      <material name="">
        <color rgba="0.65 0.65 0.65 1"/>
      </material>
    </visual>
    <collision>
      <origin rpy="0 1.57 0" xyz="0 0 0"/>
      <geometry>
        <cylinder length="0.1" radius="0.04"/>
      </geometry>
      <material name="">
        <color rgba="0.65 0.65 0.65 1"/>
      </material>
    </collision>
    <collision>
      <origin rpy="1.57 0 0" xyz="0 0.15 0"/>
      <geometry>
        <cylinder length="0.3" radius="0.02"/>
      </geometry>
      <material name="">
        <color rgba="0.65 0.65 0.65 1"/>
      </material>
    </collision>
  </link>
  <joint name="a1_j1" type="revolute">
    <origin rpy="-0.577 -0.783 -1.311" xyz="0.122 0.249 -0.0877"/>
    <parent link="base_link2"/>
    <child link="upper_arm_1"/>
    <axis xyz="-1.0 0 0"/>
    <limit effort="0" lower="-3.1416" upper="3.1416" velocity="2.618"/>
  </joint>
  <link name="lower_arm_1_pitch"/>
  <link name="lower_arm_1_yaw">
    <visual>
      <origin rpy="0 0 0" xyz="0 0 0"/>
      <geometry>
        <sphere radius="0.03"/>
      </geometry>
      <material name="">
        <color rgba="0.75 0.75 0.75 1"/>
      </material>
    </visual>
    <visual>
      <origin rpy="1.57 0 0" xyz="0 0.275 0"/>
      <geometry>
        <cylinder length="0.55" radius="0.02"/>
      </geometry>
      <material name="">
        <color rgba="0.75 0.75 0.75 1"/>
      </material>
    </visual>
    <visual>
      <origin rpy="0 0 0" xyz="0 0.55 0"/>
      <geometry>
        <sphere radius="0.03"/>
      </geometry>
      <material name="">
        <color rgba="0.75 0.75 0.7 1"/>
      </material>
    </visual>
    <collision>
      <origin rpy="0 1.57 0" xyz="0 0 0"/>
      <geometry>
        <cylinder length="0.1" radius="0.04"/>
      </geometry>
      <material name="">
        <color rgba="0.75 0.75 0.75 1"/>
      </material>
    </collision>
    <collision>
      <origin rpy="1.57 0 0" xyz="0 0.275 0"/>
      <geometry>
        <cylinder length="0.55" radius="0.02"/>
      </geometry>
      <material name="">
        <color rgba="0.75 0.75 0.75 1"/>
      </material>
    </collision>
  </link>
  <joint name="a1_j2_pitch" type="revolute">
    <origin rpy="0 0 0" xyz="0 0.3 0"/>
    <parent link="upper_arm_1"/>
    <child link="lower_arm_1_pitch"/>
    <axis xyz="-1.0 0 0"/>
    <limit effort="0" lower="-3.1416" upper="3.1416" velocity="2.618"/>
  </joint>
  <joint name="a1_j2_yaw" type="revolute">
    <origin rpy="0 0 0" xyz="0 0 0"/>
    <parent link="lower_arm_1_pitch"/>
    <child link="lower_arm_1_yaw"/>
    <axis xyz="0 0 1.0"/>
    <limit effort="0" lower="-3.1416" upper="3.1416" velocity="2.618"/>
  </joint>
  <link name="upper_arm_2">
    <visual>
      <origin rpy="0 1.57 0" xyz="0 0 0"/>
      <geometry>
        <cylinder length="0.1" radius="0.04"/>
      </geometry>
      <material name="">
        <color rgba="0.65 0.65 0.65 1"/>
      </material>
    </visual>
    <visual>
      <origin rpy="1.57 0 0" xyz="0 0.15 0"/>
      <geometry>
        <cylinder length="0.3" radius="0.02"/>
      </geometry>
      <material name="">
        <color rgba="0.65 0.65 0.65 1"/>
      </material>
    </visual>
    <collision>
      <origin rpy="0 1.57 0" xyz="0 0 0"/>
      <geometry>
        <cylinder length="0.1" radius="0.04"/>
      </geometry>
      <material name="">
        <color rgba="0.65 0.65 0.65 1"/>
      </material>
    </collision>
    <collision>
      <origin rpy="1.57 0 0" xyz="0 0.15 0"/>
      <geometry>
        <cylinder length="0.3" radius="0.02"/>
      </geometry>
      <material name="">
        <color rgba="0.65 0.65 0.65 1"/>
      </material>
    </collision>
  </link>
  <joint name="a2_j1" type="revolute">
    <origin rpy="-2.698 -0.788 -1.834" xyz="-0.122 0.249 -0.0877"/>
    <parent link="base_link2"/>
    <child link="upper_arm_2"/>
    <axis xyz="-1.0 0 0"/>
    <limit effort="0" lower="-3.1416" upper="3.1416" velocity="2.618"/>
  </joint>
  <link name="lower_arm_2_pitch"/>
  <link name="lower_arm_2_yaw">
    <visual>
      <origin rpy="0 0 0" xyz="0 0 0"/>
      <geometry>
        <sphere radius="0.03"/>
      </geometry>
      <material name="">
        <color rgba="0.75 0.75 0.75 1"/>
      </material>
    </visual>
    <visual>
      <origin rpy="1.57 0 0" xyz="0 0.275 0"/>
      <geometry>
        <cylinder length="0.55" radius="0.02"/>
      </geometry>
      <material name="">
        <color rgba="0.75 0.75 0.75 1"/>
      </material>
    </visual>
    <visual>
      <origin rpy="0 0 0" xyz="0 0.55 0"/>
      <geometry>
        <sphere radius="0.03"/>
      </geometry>
      <material name="">
        <color rgba="0.75 0.75 0.7 1"/>
      </material>
    </visual>
    <collision>
      <origin rpy="0 1.57 0" xyz="0 0 0"/>
      <geometry>
        <cylinder length="0.1" radius="0.04"/>
      </geometry>
      <material name="">
        <color rgba="0.75 0.75 0.75 1"/>
      </material>
    </collision>
    <collision>
      <origin rpy="1.57 0 0" xyz="0 0.275 0"/>
      <geometry>
        <cylinder length="0.55" radius="0.02"/>
      </geometry>
      <material name="">
        <color rgba="0.75 0.75 0.75 1"/>
      </material>
    </collision>
  </link>
  <joint name="a2_j2_pitch" type="revolute">
    <origin rpy="0 0 0" xyz="0 0.3 0"/>
    <parent link="upper_arm_2"/>
    <child link="lower_arm_2_pitch"/>
    <axis xyz="-1.0 0 0"/>
    <limit effort="0" lower="-3.1416" upper="3.1416" velocity="2.618"/>
  </joint>
  <joint name="a2_j2_yaw" type="revolute">
    <origin rpy="0 0 0" xyz="0 0 0"/>
    <parent link="lower_arm_2_pitch"/>
    <child link="lower_arm_2_yaw"/>
    <axis xyz="0 0 1.0"/>
    <limit effort="0" lower="-3.1416" upper="3.1416" velocity="2.618"/>
  </joint>
  <link name="upper_arm_3">
    <visual>
      <origin rpy="0 1.57 0" xyz="0 0 0"/>
      <geometry>
        <cylinder length="0.1" radius="0.04"/>
      </geometry>
      <material name="">
        <color rgba="0.65 0.65 0.65 1"/>
      </material>
    </visual>
    <visual>
      <origin rpy="1.57 0 0" xyz="0 0.15 0"/>
      <geometry>
        <cylinder length="0.3" radius="0.02"/>
      </geometry>
      <material name="">
        <color rgba="0.65 0.65 0.65 1"/>
      </material>
    </visual>
    <collision>
      <origin rpy="0 1.57 0" xyz="0 0 0"/>
      <geometry>
        <cylinder length="0.1" radius="0.04"/>
      </geometry>
      <material name="">
        <color rgba="0.65 0.65 0.65 1"/>
      </material>
    </collision>
    <collision>
      <origin rpy="1.57 0 0" xyz="0 0.15 0"/>
      <geometry>
        <cylinder length="0.3" radius="0.02"/>
      </geometry>
      <material name="">
        <color rgba="0.65 0.65 0.65 1"/>
      </material>
    </collision>
  </link>
  <joint name="a3_j1" type="revolute">
    <origin rpy="-0.456 -0.783 1.831" xyz="-0.122 -0.249 -0.0877"/>
    <parent link="base_link2"/>
    <child link="upper_arm_3"/>
    <axis xyz="-1.0 0 0"/>
    <limit effort="0" lower="-3.1416" upper="3.1416" velocity="2.618"/>
  </joint>
  <link name="lower_arm_3_pitch"/>
  <link name="lower_arm_3_yaw">
    <visual>
      <origin rpy="0 0 0" xyz="0 0 0"/>
      <geometry>
        <sphere radius="0.03"/>
      </geometry>
      <material name="">
        <color rgba="0.75 0.75 0.75 1"/>
      </material>
    </visual>
    <visual>
      <origin rpy="1.57 0 0" xyz="0 0.275 0"/>
      <geometry>
        <cylinder length="0.55" radius="0.02"/>
      </geometry>
      <material name="">
        <color rgba="0.75 0.75 0.75 1"/>
      </material>
    </visual>
    <visual>
      <origin rpy="0 0 0" xyz="0 0.55 0"/>
      <geometry>
        <sphere radius="0.03"/>
      </geometry>
      <material name="">
        <color rgba="0.75 0.75 0.7 1"/>
      </material>
    </visual>
    <collision>
      <origin rpy="0 1.57 0" xyz="0 0 0"/>
      <geometry>
        <cylinder length="0.1" radius="0.04"/>
      </geometry>
      <material name="">
        <color rgba="0.75 0.75 0.75 1"/>
      </material>
    </collision>
    <collision>
      <origin rpy="1.57 0 0" xyz="0 0.275 0"/>
      <geometry>
        <cylinder length="0.55" radius="0.02"/>
      </geometry>
      <material name="">
        <color rgba="0.75 0.75 0.75 1"/>
      </material>
    </collision>
  </link>
  <joint name="a3_j2_pitch" type="revolute">
    <origin rpy="0 0 0" xyz="0 0.3 0"/>
    <parent link="upper_arm_3"/>
    <child link="lower_arm_3_pitch"/>
    <axis xyz="-1.0 0 0"/>
    <limit effort="0" lower="-3.1416" upper="3.1416" velocity="2.618"/>
  </joint>
  <joint name="a3_j2_yaw" type="revolute">
    <origin rpy="0 0 0" xyz="0 0 0"/>
    <parent link="lower_arm_3_pitch"/>
    <child link="lower_arm_3_yaw"/>
    <axis xyz="0 0 1.0"/>
    <limit effort="0" lower="-3.1416" upper="3.1416" velocity="2.618"/>
  </joint>
  <link name="upper_arm_4">
    <visual>
      <origin rpy="0 1.57 0" xyz="0 0 0"/>
      <geometry>
        <cylinder length="0.1" radius="0.04"/>
      </geometry>
      <material name="">
        <color rgba="0.65 0.65 0.65 1"/>
      </material>
    </visual>
    <visual>
      <origin rpy="1.57 0 0" xyz="0 0.15 0"/>
      <geometry>
        <cylinder length="0.3" radius="0.02"/>
      </geometry>
      <material name="">
        <color rgba="0.65 0.65 0.65 1"/>
      </material>
    </visual>
    <collision>
      <origin rpy="0 1.57 0" xyz="0 0 0"/>
      <geometry>
        <cylinder length="0.1" radius="0.04"/>
      </geometry>
      <material name="">
        <color rgba="0.65 0.65 0.65 1"/>
      </material>
    </collision>
    <collision>
      <origin rpy="1.57 0 0" xyz="0 0.15 0"/>
      <geometry>
        <cylinder length="0.3" radius="0.02"/>
      </geometry>
      <material name="">
        <color rgba="0.65 0.65 0.65 1"/>
      </material>
    </collision>
  </link>
  <joint name="a4_j1" type="revolute">
    <origin rpy="-2.531 -0.788 1.307" xyz="0.122 -0.249 -0.0877"/>
    <parent link="base_link2"/>
    <child link="upper_arm_4"/>
    <axis xyz="-1.0 0 0"/>
    <limit effort="0" lower="-3.1416" upper="3.1416" velocity="2.618"/>
  </joint>
  <link name="lower_arm_4_pitch"/>
  <link name="lower_arm_4_yaw">
    <visual>
      <origin rpy="0 0 0" xyz="0 0 0"/>
      <geometry>
        <sphere radius="0.03"/>
      </geometry>
      <material name="">
        <color rgba="0.75 0.75 0.75 1"/>
      </material>
    </visual>
    <visual>
      <origin rpy="1.57 0 0" xyz="0 0.275 0"/>
      <geometry>
        <cylinder length="0.55" radius="0.02"/>
      </geometry>
      <material name="">
        <color rgba="0.75 0.75 0.75 1"/>
      </material>
    </visual>
    <visual>
      <origin rpy="0 0 0" xyz="0 0.55 0"/>
      <geometry>
        <sphere radius="0.03"/>
      </geometry>
      <material name="">
        <color rgba="0.75 0.75 0.7 1"/>
      </material>
    </visual>
    <collision>
      <origin rpy="0 1.57 0" xyz="0 0 0"/>
      <geometry>
        <cylinder length="0.1" radius="0.04"/>
      </geometry>
      <material name="">
        <color rgba="0.75 0.75 0.75 1"/>
      </material>
    </collision>
    <collision>
      <origin rpy="1.57 0 0" xyz="0 0.275 0"/>
      <geometry>
        <cylinder length="0.55" radius="0.02"/>
      </geometry>
      <material name="">
        <color rgba="0.75 0.75 0.75 1"/>
      </material>
    </collision>
  </link>
  <joint name="a4_j2_pitch" type="revolute">
    <origin rpy="0 0 0" xyz="0 0.3 0"/>
    <parent link="upper_arm_4"/>
    <child link="lower_arm_4_pitch"/>
    <axis xyz="-1.0 0 0"/>
    <limit effort="0" lower="-3.1416" upper="3.1416" velocity="2.618"/>
  </joint>
  <joint name="a4_j2_yaw" type="revolute">
    <origin rpy="0 0 0" xyz="0 0 0"/>
    <parent link="lower_arm_4_pitch"/>
    <child link="lower_arm_4_yaw"/>
    <axis xyz="0 0 1.0"/>
    <limit effort="0" lower="-3.1416" upper="3.1416" velocity="2.618"/>
  </joint>
  <link name="ee_link_r">
    
  </link>
  <joint name="ee_joint_roll" type="revolute">
    <origin rpy="0 0 0" xyz="0 0.550 0"/>
    <parent link="lower_arm_1_yaw"/>
    <child link="ee_link_r"/>
    <axis xyz="0 0 1"/>
    <limit effort="0" lower="-3.1416" upper="3.1416" velocity="2.618"/>
  </joint>
  <link name="ee_link_p">
    
  </link>
  <joint name="ee_joint_pitch" type="revolute">
    <origin rpy="0 0 0" xyz="0 0 0"/>
    <parent link="ee_link_r"/>
    <child link="ee_link_p"/>
    <axis xyz="1 0 0"/>
    <limit effort="0" lower="-3.1416" upper="3.1416" velocity="2.618"/>
  </joint>
  <link name="ee_link_y">
    <visual>
      <origin rpy="0 0 0" xyz="0 0 0"/>
      <geometry>
        <mesh filename="package://ragnar_support/meshes/ee_link_y.STL"/>
      </geometry>
      <material name="">
        <color rgba="1 0 0 1"/>
      </material>
    </visual>
    <collision>
      <origin rpy="0 0 0" xyz="0 0 0"/>
      <geometry>
        <mesh filename="package://ragnar_support/meshes/ee_link_y.STL"/>
      </geometry>
    </collision>
  </link>
  <joint name="ee_joint_yaw" type="revolute">
    <origin rpy="5.55111512312578E-17 -2.77555756156289E-17 0" xyz="0 0 0"/>
    <parent link="ee_link_p"/>
    <child link="ee_link_y"/>
    <axis xyz="0 -1 0"/>
    <limit effort="0" lower="-3.1416" upper="3.1416" velocity="2.618"/>
  </joint>
</robot>

