<?xml version="1.0" ?>
<robot name="Ragnar" xmlns:xacro="http://ros.org/wiki/xacro">
  

  <link name="base_link"/>

  <link name="base_link2">
    <inertial>
      <origin xyz="-4.80572213006859E-06 9.64495107789746E-06 -0.0184680705713898" rpy="0 0 0" />
      <mass value="26.5217124601092" />
      <inertia ixx="0.936457909215975" ixy="-0.00108838510526368" ixz="1.58187182756307E-06"
        iyy="1.50216890338436" iyz="1.0107984651762E-05" izz="2.28323593907717" />
    </inertial>
    <visual>
      <origin xyz="0 0 0" rpy="0 0 0" />
      <geometry>
        <mesh filename="package://ragnar_support/meshes/base_link.STL" />
      </geometry>
      <material name="">
        <color rgba="0.5 0.5 0.5 1" />
      </material>
    </visual>
    <collision>
      <origin xyz="0 0 0" rpy="0 0 0" />
      <geometry>
        <mesh filename="package://ragnar_support/meshes/base_link.STL" />
      </geometry>
    </collision>
  </link>

 <joint name="base_rotate" type="fixed">
    <origin xyz="0 0 0.05" rpy="0 0 1.57" />
    <parent link="base_link" />
    <child link="base_link2" />
    <axis xyz="0 0 0" />
  </joint>

<xacro:include filename="$(find ragnar_support)/urdf/ragnar_upper2_macro.xacro"/>
  <xacro:ragnar_upper2 num="1" x="0.122" y="0.249" z="-0.0877" r="-0.577" p="-0.783" w="-1.311" d1="0.300" d2="0.550"/>
<xacro:include filename="$(find ragnar_support)/urdf/ragnar_upper2_macro.xacro"/>
  <xacro:ragnar_upper2 num="2" x="-0.122" y="0.249" z="-0.0877" r="-2.698" p="-0.788" w="-1.834" d1="0.300" d2="0.550"/>
<xacro:include filename="$(find ragnar_support)/urdf/ragnar_upper2_macro.xacro"/>
  <xacro:ragnar_upper2 num="3" x="-0.122" y="-0.249" z="-0.0877" r="-0.456" p="-0.783" w="1.831" d1="0.300" d2="0.550"/>
<xacro:include filename="$(find ragnar_support)/urdf/ragnar_upper2_macro.xacro"/>
  <xacro:ragnar_upper2 num="4" x="0.122" y="-0.249" z="-0.0877" r="-2.531" p="-0.788" w="1.307" d1="0.300" d2="0.550"/>



<link name="ee_link_r">
    
  </link>
  <joint name="ee_joint_roll" type="revolute">
    <origin xyz="0 0.550 0"
      rpy="0 0 0" />
    <parent link="lower_arm_1_yaw" />
    <child link="ee_link_r" />
    <axis xyz="0 0 1" />
    <limit effort="0" lower="-3.1416" upper="3.1416" velocity="2.618"/>
  </joint>

  <link name="ee_link_p">
    
  </link>
  <joint name="ee_joint_pitch" type="revolute">
    <origin xyz="0 0 0" rpy="0 0 0" />
    <parent link="ee_link_r" />
    <child link="ee_link_p" />
    <axis xyz="1 0 0" />
<limit effort="0" lower="-3.1416" upper="3.1416" velocity="2.618"/>
  </joint>
  <link name="ee_link_y">
    <visual>
      <origin xyz="0 0 0" rpy="0 0 0" />
      <geometry>
        <mesh filename="package://ragnar_support/meshes/ee_link_y.STL" />
      </geometry>
      <material name="">
        <color rgba="1 0 0 1" />
      </material>
    </visual>
    <collision>
      <origin xyz="0 0 0" rpy="0 0 0" />
      <geometry>
        <mesh filename="package://ragnar_support/meshes/ee_link_y.STL" />
      </geometry>
    </collision>
  </link>
  <joint name="ee_joint_yaw" type="revolute">
    <origin xyz="0 0 0" rpy="5.55111512312578E-17 -2.77555756156289E-17 0" />
    <parent link="ee_link_p" />
    <child link="ee_link_y" />
    <axis xyz="0 -1 0" />
<limit effort="0" lower="-3.1416" upper="3.1416" velocity="2.618"/>
  </joint>
</robot>
